<?xml version="1.0"?>

<robot xmlns:sensor="http://playerstage.sourceforge.net/gazebo/xmlschema/#sensor"
      xmlns:controller="http://playerstage.sourceforge.net/gazebo/xmlschema/#controller"
      xmlns:interface="http://playerstage.sourceforge.net/gazebo/xmlschema/#interface"
      xmlns:xacro="http://ros.org/wiki/xacro">

  <include filename="$(find reem_description)/urdf/deg_to_rad.xacro" />
  <include filename="$(find reem_robocup_description)/urdf/hand/hand.gazebo.xacro" />
  <include filename="$(find reem_robocup_description)/urdf/hand/hand.transmission.xacro" />

  <xacro:macro name="rh1_hand" params="name side reflect">

    <!-- Links -->

    <link name="hand_${side}_wrist_link">
      <inertial>
        <origin xyz="0.01747 ${reflect * 0.0014} ${reflect * 0.128}" rpy="0 0 0" />
        <mass value="0.8" />
        <inertia ixx="0"  ixy="0"  ixz="0" iyy="0" iyz="0" izz="0" />
      </inertial>
      <visual>
        <origin xyz="0 0 ${reflect * 0.08}" rpy="0 0 0" />
        <geometry>
          <box size="0.075 0.075 0.08" />
        </geometry>
        <material name="Grey" />
      </visual>
      <collision>
        <origin xyz="0 0 ${reflect * 0.08}" rpy="0 0 0" />
        <geometry>
          <box size="0.075 0.075 0.08" />
        </geometry>
      </collision>
    </link>

    <link name="hand_${side}_link">
      <!-- TODO: define meaningful mas and inertia -->
      <inertial>
        <origin xyz="0.01 0.0675 0" rpy="0 0 0" />
        <mass value="0.1" />
        <inertia ixx="0"  ixy="0"  ixz="0" iyy="0" iyz="0" izz="0" />
      </inertial>
      <visual>
        <origin xyz="0.01 0.0675 0" rpy="0 0 0" />
        <geometry>
          <box size="0.02 0.135 0.075" />
        </geometry>
        <material name="DarkGrey" />
      </visual>
      <collision>
        <origin xyz="0.01 0.0675 0" rpy="0 0 0" />
        <geometry>
          <box size="0.02 0.135 0.075" />
        </geometry>
      </collision>
    </link>

    <link name="hand_${side}_thumb_link">
      <!-- TODO: define meaningful mass and inertia -->
      <inertial>
        <origin xyz="0.01 0.0675 0" rpy="0 0 0" />
        <mass value="0.1" />
        <inertia ixx="0"  ixy="0"  ixz="0" iyy="0" iyz="0" izz="0" />
      </inertial>
      <visual>
        <origin xyz="0 0 ${reflect * 0.015}" rpy="0 0 0" />
        <geometry>
          <cylinder radius="0.01" length="0.09" />
        </geometry>
        <material name="DarkGrey" />
      </visual>
      <collision>
        <origin xyz="0 0 ${reflect * 0.015}" rpy="0 0 0" />
        <geometry>
          <cylinder radius="0.01" length="0.09" />
        </geometry>
      </collision>
    </link>

    <link name="hand_${side}_palm_link">
      <inertial>
        <origin xyz="0 0 0" rpy="0 0 0" />
        <mass value="0.1" />
        <inertia ixx="0"  ixy="0"  ixz="0" iyy="0" iyz="0" izz="0" />
      </inertial>
      <visual>
        <origin xyz="-0.005 0 0" rpy="0 0 0" />
        <geometry>
          <box size="0.01 0.01 0.01" />
        </geometry>
        <material name="DarkGrey" />
      </visual>
    </link>

    <!-- Joints -->
    <joint name="hand_${side}_wrist_joint" type="fixed">
      <parent link="arm_${side}_7_link" />
      <child link="hand_${side}_wrist_link" />
      <origin xyz="0 0 0" rpy="0 0 0" />
    </joint>

    <joint name="hand_${side}_palm_joint" type="fixed">
      <parent link="hand_${side}_wrist_link" />
      <child link="hand_${side}_palm_link" />
      <origin xyz="0 0 ${reflect * 0.12}" rpy="${90.0 * deg_to_rad} ${-reflect * 90.0 * deg_to_rad} 0" />
    </joint>

    <joint name="hand_${side}_joint" type="revolute">
      <parent link="arm_${side}_7_link" />
      <child link="hand_${side}_link" />
      <origin xyz="0.03 0 ${reflect * 0.12}" rpy="${reflect * 90.0 * deg_to_rad} 0 0" />
      <axis xyz="0 0 1" />
      <limit lower="0" upper="${90.0 * deg_to_rad}" effort="0.0" velocity="1.0" />
      <dynamics friction="1.0" damping="0.0"/>
    </joint>

    <joint name="hand_${side}_thumb_joint" type="fixed">
      <parent link="arm_${side}_7_link" />
      <child link="hand_${side}_thumb_link" />
      <origin xyz="-0.05 0 ${reflect * 0.12}" rpy="0 0 0" />
    </joint>

    <!-- extensions -->
    <xacro:rh1_hand_gazebo side="${side}" color="Gazebo/LightGrey" />
    <xacro:rh1_hand_gazebo side="${side}" color="Gazebo/Grey" />
    <xacro:rh1_hand_transmission name="${name}" side="${side}" />

  </xacro:macro>

</robot>
